Workbook

Sheet Dashboard
A1: WCAG 2.2 Accessibility Audit
A5: Interactive checklist · Levels A, AA & AAA · For Strategists, Designers, Developers & QA Teams
A7: Project Details
A8: Client Name | B8: The Bank Workers Charity
A9: Website URL | B9: https://www.bwcharity.org.uk/
A10: Audit Date | B10: 46177
A11: Auditor | B11: Charlotte Coveney
A12: Section | B12: Total Items | C12: Pass | D12: Fail / Issue | E12: N/A | F12: Score
A13: Section 1 — Content | B13: =COUNTIF(Content!F3:F24,"Pass")+COUNTIF(Content!F3:F24,"Fail")+COUNTIF(Content!F3:F24,"N/A")+COUNTIF(Content!F3:F24,"Not Tested") -> 19 | C13: =COUNTIF(Content!F3:F24,"Pass") -> 8 | D13: =COUNTIF(Content!F3:F24,"Fail") -> 6 | E13: =COUNTIF(Content!F3:F24,"N/A") -> 5 | F13: =IF(B13=0,"—",TEXT((C13+E13)/B13,"0%")&" Pass") -> 68% Pass
A14: Section 2 — Design | B14: =COUNTIF(Design!F3:F29,"Pass")+COUNTIF(Design!F3:F29,"Fail")+COUNTIF(Design!F3:F29,"N/A")+COUNTIF(Design!F3:F29,"Not Tested") -> 22 | C14: =COUNTIF(Design!F3:F29,"Pass") -> 15 | D14: =COUNTIF(Design!F3:F29,"Fail") -> 4 | E14: =COUNTIF(Design!F3:F29,"N/A") -> 3 | F14: =IF(B14=0,"—",TEXT((C14+E14)/B14,"0%")&" Pass") -> 82% Pass
A15: Section 3 — Development | B15: =COUNTIF(Development!F3:F28,"Pass")+COUNTIF(Development!F3:F28,"Fail")+COUNTIF(Development!F3:F28,"N/A")+COUNTIF(Development!F3:F28,"Not Tested") -> 21 | C15: =COUNTIF(Development!F3:F28,"Pass") -> 15 | D15: =COUNTIF(Development!F3:F28,"Fail") -> 5 | E15: =COUNTIF(Development!F3:F28,"N/A") -> 1 | F15: =IF(B15=0,"—",TEXT((C15+E15)/B15,"0%")&" Pass") -> 76% Pass
A16: Section 4 — QA Keyboard | B16: =COUNTIF(QA_Keyboard!F3:F14,"Pass")+COUNTIF(QA_Keyboard!F3:F14,"Fail")+COUNTIF(QA_Keyboard!F3:F14,"N/A")+COUNTIF(QA_Keyboard!F3:F14,"Not Tested") -> 10 | C16: =COUNTIF(QA_Keyboard!F3:F14,"Pass") -> 5 | D16: =COUNTIF(QA_Keyboard!F3:F14,"Fail") -> 5 | E16: =COUNTIF(QA_Keyboard!F3:F14,"N/A") -> 0 | F16: =IF(B16=0,"—",TEXT((C16+E16)/B16,"0%")&" Pass") -> 50% Pass
A17: Section 5 — QA Forms | B17: =COUNTIF(QA_Forms!F3:F15,"Pass")+COUNTIF(QA_Forms!F3:F15,"Fail")+COUNTIF(QA_Forms!F3:F15,"N/A")+COUNTIF(QA_Forms!F3:F15,"Not Tested") -> 11 | C17: =COUNTIF(QA_Forms!F3:F15,"Pass") -> 9 | D17: =COUNTIF(QA_Forms!F3:F15,"Fail") -> 1 | E17: =COUNTIF(QA_Forms!F3:F15,"N/A") -> 1 | F17: =IF(B17=0,"—",TEXT((C17+E17)/B17,"0%")&" Pass") -> 91% Pass
A18: Section 6 — QA Colour | B18: =COUNTIF(QA_Colour!F3:F8,"Pass")+COUNTIF(QA_Colour!F3:F8,"Fail")+COUNTIF(QA_Colour!F3:F8,"N/A")+COUNTIF(QA_Colour!F3:F8,"Not Tested") -> 5 | C18: =COUNTIF(QA_Colour!F3:F8,"Pass") -> 5 | D18: =COUNTIF(QA_Colour!F3:F8,"Fail") -> 0 | E18: =COUNTIF(QA_Colour!F3:F8,"N/A") -> 0 | F18: =IF(B18=0,"—",TEXT((C18+E18)/B18,"0%")&" Pass") -> 100% Pass
A19: Section 7 — QA Screen Reader | B19: =COUNTIF(QA_ScreenReader!F3:F15,"Pass")+COUNTIF(QA_ScreenReader!F3:F15,"Fail")+COUNTIF(QA_ScreenReader!F3:F15,"N/A")+COUNTIF(QA_ScreenReader!F3:F15,"Not Tested") -> 11 | C19: =COUNTIF(QA_ScreenReader!F3:F15,"Pass") -> 7 | D19: =COUNTIF(QA_ScreenReader!F3:F15,"Fail") -> 3 | E19: =COUNTIF(QA_ScreenReader!F3:F15,"N/A") -> 1 | F19: =IF(B19=0,"—",TEXT((C19+E19)/B19,"0%")&" Pass") -> 73% Pass
A20: Section 8 — QA Media | B20: =COUNTIF(QA_Media!F3:F16,"Pass")+COUNTIF(QA_Media!F3:F16,"Fail")+COUNTIF(QA_Media!F3:F16,"N/A")+COUNTIF(QA_Media!F3:F16,"Not Tested") -> 11 | C20: =COUNTIF(QA_Media!F3:F16,"Pass") -> 2 | D20: =COUNTIF(QA_Media!F3:F16,"Fail") -> 4 | E20: =COUNTIF(QA_Media!F3:F16,"N/A") -> 5 | F20: =IF(B20=0,"—",TEXT((C20+E20)/B20,"0%")&" Pass") -> 64% Pass
A21: TOTAL | B21: =SUM(B13:B20) -> 110 | C21: =SUM(C13:C20) -> 66 | D21: =SUM(D13:D20) -> 28 | E21: =SUM(E13:E20) -> 16 | F21: =IF(B21=0,"—",TEXT((C21+E21)/B21,"0%")&" Pass") -> 75% Pass
A24: Conformance Summary
A25: Level | B25: Required | C25: Pass / N/A | D25: Fail | E25: Not Tested | F25: Conformance
A26: A | B26: =SUMPRODUCT((Content!C3:C24="A")*1)+SUMPRODUCT((Design!C3:C29="A")*1)+SUMPRODUCT((Development!C3:C28="A")*1)+SUMPRODUCT((QA_Keyboard!C3:C14="A")*1)+SUMPRODUCT((QA_Forms!C3:C15="A")*1)+SUMPRODUCT((QA_Colour!C3:C8="A")*1)+SUMPRODUCT((QA_ScreenReader!C3:C15="A")*1)+SUMPRODUCT((QA_Media!C3:C16="A")*1) -> 58 | C26: =SUMPRODUCT((Content!C3:C24="A")*((Content!F3:F24="Pass")+(Content!F3:F24="N/A")))+SUMPRODUCT((Design!C3:C29="A")*((Design!F3:F29="Pass")+(Design!F3:F29="N/A")))+SUMPRODUCT((Development!C3:C28="A")*((Development!F3:F28="Pass")+(Development!F3:F28="N/A")))+SUMPRODUCT((QA_Keyboard!C3:C14="A")*((QA_Keyboard!F3:F14="Pass")+(QA_Keyboard!F3:F14="N/A")))+SUMPRODUCT((QA_Forms!C3:C15="A")*((QA_Forms!F3:F15="Pass")+(QA_Forms!F3:F15="N/A")))+SUMPRODUCT((QA_Colour!C3:C8="A")*((QA_Colour!F3:F8="Pass")+(QA_Colour!F3:F8="N/A")))+SUMPRODUCT((QA_ScreenReader!C3:C15="A")*((QA_ScreenReader!F3:F15="Pass")+(QA_ScreenReader!F3:F15="N/A")))+SUMPRODUCT((QA_Media!C3:C16="A")*((QA_Media!F3:F16="Pass")+(QA_Media!F3:F16="N/A"))) -> 47 | D26: =SUMPRODUCT((Content!C3:C24="A")*(Content!F3:F24="Fail"))+SUMPRODUCT((Design!C3:C29="A")*(Design!F3:F29="Fail"))+SUMPRODUCT((Development!C3:C28="A")*(Development!F3:F28="Fail"))+SUMPRODUCT((QA_Keyboard!C3:C14="A")*(QA_Keyboard!F3:F14="Fail"))+SUMPRODUCT((QA_Forms!C3:C15="A")*(QA_Forms!F3:F15="Fail"))+SUMPRODUCT((QA_Colour!C3:C8="A")*(QA_Colour!F3:F8="Fail"))+SUMPRODUCT((QA_ScreenReader!C3:C15="A")*(QA_ScreenReader!F3:F15="Fail"))+SUMPRODUCT((QA_Media!C3:C16="A")*(QA_Media!F3:F16="Fail")) -> 11 | E26: =SUMPRODUCT((Content!C3:C24="A")*(Content!F3:F24="Not Tested"))+SUMPRODUCT((Design!C3:C29="A")*(Design!F3:F29="Not Tested"))+SUMPRODUCT((Development!C3:C28="A")*(Development!F3:F28="Not Tested"))+SUMPRODUCT((QA_Keyboard!C3:C14="A")*(QA_Keyboard!F3:F14="Not Tested"))+SUMPRODUCT((QA_Forms!C3:C15="A")*(QA_Forms!F3:F15="Not Tested"))+SUMPRODUCT((QA_Colour!C3:C8="A")*(QA_Colour!F3:F8="Not Tested"))+SUMPRODUCT((QA_ScreenReader!C3:C15="A")*(QA_ScreenReader!F3:F15="Not Tested"))+SUMPRODUCT((QA_Media!C3:C16="A")*(QA_Media!F3:F16="Not Tested")) -> 0 | F26: =IF(D26>0,"Does Not Conform",IF(E26>0,"Incomplete","Conforms")) -> Does Not Conform
A27: AA | B27: =SUMPRODUCT((Content!C3:C24="AA")*1)+SUMPRODUCT((Design!C3:C29="AA")*1)+SUMPRODUCT((Development!C3:C28="AA")*1)+SUMPRODUCT((QA_Keyboard!C3:C14="AA")*1)+SUMPRODUCT((QA_Forms!C3:C15="AA")*1)+SUMPRODUCT((QA_Colour!C3:C8="AA")*1)+SUMPRODUCT((QA_ScreenReader!C3:C15="AA")*1)+SUMPRODUCT((QA_Media!C3:C16="AA")*1) -> 37 | C27: =SUMPRODUCT((Content!C3:C24="AA")*((Content!F3:F24="Pass")+(Content!F3:F24="N/A")))+SUMPRODUCT((Design!C3:C29="AA")*((Design!F3:F29="Pass")+(Design!F3:F29="N/A")))+SUMPRODUCT((Development!C3:C28="AA")*((Development!F3:F28="Pass")+(Development!F3:F28="N/A")))+SUMPRODUCT((QA_Keyboard!C3:C14="AA")*((QA_Keyboard!F3:F14="Pass")+(QA_Keyboard!F3:F14="N/A")))+SUMPRODUCT((QA_Forms!C3:C15="AA")*((QA_Forms!F3:F15="Pass")+(QA_Forms!F3:F15="N/A")))+SUMPRODUCT((QA_Colour!C3:C8="AA")*((QA_Colour!F3:F8="Pass")+(QA_Colour!F3:F8="N/A")))+SUMPRODUCT((QA_ScreenReader!C3:C15="AA")*((QA_ScreenReader!F3:F15="Pass")+(QA_ScreenReader!F3:F15="N/A")))+SUMPRODUCT((QA_Media!C3:C16="AA")*((QA_Media!F3:F16="Pass")+(QA_Media!F3:F16="N/A"))) -> 27 | D27: =SUMPRODUCT((Content!C3:C24="AA")*(Content!F3:F24="Fail"))+SUMPRODUCT((Design!C3:C29="AA")*(Design!F3:F29="Fail"))+SUMPRODUCT((Development!C3:C28="AA")*(Development!F3:F28="Fail"))+SUMPRODUCT((QA_Keyboard!C3:C14="AA")*(QA_Keyboard!F3:F14="Fail"))+SUMPRODUCT((QA_Forms!C3:C15="AA")*(QA_Forms!F3:F15="Fail"))+SUMPRODUCT((QA_Colour!C3:C8="AA")*(QA_Colour!F3:F8="Fail"))+SUMPRODUCT((QA_ScreenReader!C3:C15="AA")*(QA_ScreenReader!F3:F15="Fail"))+SUMPRODUCT((QA_Media!C3:C16="AA")*(QA_Media!F3:F16="Fail")) -> 10 | E27: =SUMPRODUCT((Content!C3:C24="AA")*(Content!F3:F24="Not Tested"))+SUMPRODUCT((Design!C3:C29="AA")*(Design!F3:F29="Not Tested"))+SUMPRODUCT((Development!C3:C28="AA")*(Development!F3:F28="Not Tested"))+SUMPRODUCT((QA_Keyboard!C3:C14="AA")*(QA_Keyboard!F3:F14="Not Tested"))+SUMPRODUCT((QA_Forms!C3:C15="AA")*(QA_Forms!F3:F15="Not Tested"))+SUMPRODUCT((QA_Colour!C3:C8="AA")*(QA_Colour!F3:F8="Not Tested"))+SUMPRODUCT((QA_ScreenReader!C3:C15="AA")*(QA_ScreenReader!F3:F15="Not Tested"))+SUMPRODUCT((QA_Media!C3:C16="AA")*(QA_Media!F3:F16="Not Tested")) -> 0 | F27: =IF(D27>0,"Does Not Conform",IF(E27>0,"Incomplete","Conforms")) -> Does Not Conform
A28: AAA | B28: =SUMPRODUCT((Content!C3:C24="AAA")*1)+SUMPRODUCT((Design!C3:C29="AAA")*1)+SUMPRODUCT((Development!C3:C28="AAA")*1)+SUMPRODUCT((QA_Keyboard!C3:C14="AAA")*1)+SUMPRODUCT((QA_Forms!C3:C15="AAA")*1)+SUMPRODUCT((QA_Colour!C3:C8="AAA")*1)+SUMPRODUCT((QA_ScreenReader!C3:C15="AAA")*1)+SUMPRODUCT((QA_Media!C3:C16="AAA")*1) -> 4 | C28: =SUMPRODUCT((Content!C3:C24="AAA")*((Content!F3:F24="Pass")+(Content!F3:F24="N/A")))+SUMPRODUCT((Design!C3:C29="AAA")*((Design!F3:F29="Pass")+(Design!F3:F29="N/A")))+SUMPRODUCT((Development!C3:C28="AAA")*((Development!F3:F28="Pass")+(Development!F3:F28="N/A")))+SUMPRODUCT((QA_Keyboard!C3:C14="AAA")*((QA_Keyboard!F3:F14="Pass")+(QA_Keyboard!F3:F14="N/A")))+SUMPRODUCT((QA_Forms!C3:C15="AAA")*((QA_Forms!F3:F15="Pass")+(QA_Forms!F3:F15="N/A")))+SUMPRODUCT((QA_Colour!C3:C8="AAA")*((QA_Colour!F3:F8="Pass")+(QA_Colour!F3:F8="N/A")))+SUMPRODUCT((QA_ScreenReader!C3:C15="AAA")*((QA_ScreenReader!F3:F15="Pass")+(QA_ScreenReader!F3:F15="N/A")))+SUMPRODUCT((QA_Media!C3:C16="AAA")*((QA_Media!F3:F16="Pass")+(QA_Media!F3:F16="N/A"))) -> 0 | D28: =SUMPRODUCT((Content!C3:C24="AAA")*(Content!F3:F24="Fail"))+SUMPRODUCT((Design!C3:C29="AAA")*(Design!F3:F29="Fail"))+SUMPRODUCT((Development!C3:C28="AAA")*(Development!F3:F28="Fail"))+SUMPRODUCT((QA_Keyboard!C3:C14="AAA")*(QA_Keyboard!F3:F14="Fail"))+SUMPRODUCT((QA_Forms!C3:C15="AAA")*(QA_Forms!F3:F15="Fail"))+SUMPRODUCT((QA_Colour!C3:C8="AAA")*(QA_Colour!F3:F8="Fail"))+SUMPRODUCT((QA_ScreenReader!C3:C15="AAA")*(QA_ScreenReader!F3:F15="Fail"))+SUMPRODUCT((QA_Media!C3:C16="AAA")*(QA_Media!F3:F16="Fail")) -> 4 | E28: =SUMPRODUCT((Content!C3:C24="AAA")*(Content!F3:F24="Not Tested"))+SUMPRODUCT((Design!C3:C29="AAA")*(Design!F3:F29="Not Tested"))+SUMPRODUCT((Development!C3:C28="AAA")*(Development!F3:F28="Not Tested"))+SUMPRODUCT((QA_Keyboard!C3:C14="AAA")*(QA_Keyboard!F3:F14="Not Tested"))+SUMPRODUCT((QA_Forms!C3:C15="AAA")*(QA_Forms!F3:F15="Not Tested"))+SUMPRODUCT((QA_Colour!C3:C8="AAA")*(QA_Colour!F3:F8="Not Tested"))+SUMPRODUCT((QA_ScreenReader!C3:C15="AAA")*(QA_ScreenReader!F3:F15="Not Tested"))+SUMPRODUCT((QA_Media!C3:C16="AAA")*(QA_Media!F3:F16="Not Tested")) -> 0 | F28: =IF(D28>0,"Does Not Conform",IF(E28>0,"Incomplete","Conforms")) -> Does Not Conform
A29: BP | B29: =SUMPRODUCT((Content!C3:C24="BP")*1)+SUMPRODUCT((Design!C3:C29="BP")*1)+SUMPRODUCT((Development!C3:C28="BP")*1)+SUMPRODUCT((QA_Keyboard!C3:C14="BP")*1)+SUMPRODUCT((QA_Forms!C3:C15="BP")*1)+SUMPRODUCT((QA_Colour!C3:C8="BP")*1)+SUMPRODUCT((QA_ScreenReader!C3:C15="BP")*1)+SUMPRODUCT((QA_Media!C3:C16="BP")*1) -> 11 | C29: =SUMPRODUCT((Content!C3:C24="BP")*((Content!F3:F24="Pass")+(Content!F3:F24="N/A")))+SUMPRODUCT((Design!C3:C29="BP")*((Design!F3:F29="Pass")+(Design!F3:F29="N/A")))+SUMPRODUCT((Development!C3:C28="BP")*((Development!F3:F28="Pass")+(Development!F3:F28="N/A")))+SUMPRODUCT((QA_Keyboard!C3:C14="BP")*((QA_Keyboard!F3:F14="Pass")+(QA_Keyboard!F3:F14="N/A")))+SUMPRODUCT((QA_Forms!C3:C15="BP")*((QA_Forms!F3:F15="Pass")+(QA_Forms!F3:F15="N/A")))+SUMPRODUCT((QA_Colour!C3:C8="BP")*((QA_Colour!F3:F8="Pass")+(QA_Colour!F3:F8="N/A")))+SUMPRODUCT((QA_ScreenReader!C3:C15="BP")*((QA_ScreenReader!F3:F15="Pass")+(QA_ScreenReader!F3:F15="N/A")))+SUMPRODUCT((QA_Media!C3:C16="BP")*((QA_Media!F3:F16="Pass")+(QA_Media!F3:F16="N/A"))) -> 8 | D29: =SUMPRODUCT((Content!C3:C24="BP")*(Content!F3:F24="Fail"))+SUMPRODUCT((Design!C3:C29="BP")*(Design!F3:F29="Fail"))+SUMPRODUCT((Development!C3:C28="BP")*(Development!F3:F28="Fail"))+SUMPRODUCT((QA_Keyboard!C3:C14="BP")*(QA_Keyboard!F3:F14="Fail"))+SUMPRODUCT((QA_Forms!C3:C15="BP")*(QA_Forms!F3:F15="Fail"))+SUMPRODUCT((QA_Colour!C3:C8="BP")*(QA_Colour!F3:F8="Fail"))+SUMPRODUCT((QA_ScreenReader!C3:C15="BP")*(QA_ScreenReader!F3:F15="Fail"))+SUMPRODUCT((QA_Media!C3:C16="BP")*(QA_Media!F3:F16="Fail")) -> 3 | E29: =SUMPRODUCT((Content!C3:C24="BP")*(Content!F3:F24="Not Tested"))+SUMPRODUCT((Design!C3:C29="BP")*(Design!F3:F29="Not Tested"))+SUMPRODUCT((Development!C3:C28="BP")*(Development!F3:F28="Not Tested"))+SUMPRODUCT((QA_Keyboard!C3:C14="BP")*(QA_Keyboard!F3:F14="Not Tested"))+SUMPRODUCT((QA_Forms!C3:C15="BP")*(QA_Forms!F3:F15="Not Tested"))+SUMPRODUCT((QA_Colour!C3:C8="BP")*(QA_Colour!F3:F8="Not Tested"))+SUMPRODUCT((QA_ScreenReader!C3:C15="BP")*(QA_ScreenReader!F3:F15="Not Tested"))+SUMPRODUCT((QA_Media!C3:C16="BP")*(QA_Media!F3:F16="Not Tested")) -> 0 | F29: =IF(D29>0,"Does Not Conform",IF(E29>0,"Incomplete","Conforms")) -> Does Not Conform
A30: =IF(F26="Does Not Conform","This audit does not currently conform to WCAG 2.2 Level A.",IF(F27="Does Not Conform","This audit currently conforms to WCAG 2.2 Level A only.",IF(F28="Does Not Conform","This audit currently conforms to WCAG 2.2 Level AA.",IF(F28="Conforms","This audit currently conforms to WCAG 2.2 Level AAA.","")))) -> This audit does not currently conform to WCAG 2.2 Level A.
A33: WCAG Conformance Levels
A34: A | B34: Essential — assistive tech may fail without this
A35: AA | B35: Ideal / Legal minimum — required for most public services
A36: AAA | B36: Specialised — maximum inclusion target
A37: BP | B37: Best Practice — not formal WCAG but strongly recommended
A39: Status Key
A40: Pass | B40: Criterion confirmed as meeting requirements
A41: Fail | B41: Criterion fails — issue found, action required
A42: N/A | B42: Not applicable to this project / page
A43: Not Tested | B43: Not yet reviewed

Sheet Issues Log
A1: Issues Log — WCAG Accessibility Audit
A2: Client | B2: =Dashboard!$B$8 -> The Bank Workers Charity
A3: Website | B3: =Dashboard!$B$9 -> https://www.bwcharity.org.uk/
A4: Audit Date | B4: =Dashboard!$B$10 -> 46177
A5: Auditor | B5: =Dashboard!$B$11 -> Charlotte Coveney
A6: Fail items only — auto-populated from checklist sheets as you work through each section.
A7: Section | B7: WCAG Criterion | C7: Level | D7: Description | E7: Owner | F7: Status | G7: Notes
A8: =IFERROR(__xludf.DUMMYFUNCTION("VSTACK(IFERROR(FILTER(HSTACK(ARRAYFORMULA(IF(ROW(Content!B3:B24)-ROW(Content!B3)+1>0,""Section 1 — Content"","""")),Content!B3:B24,Content!C3:C24,Content!D3:D24,Content!E3:E24,Content!F3:F24,Content!G3:G24),Content!F3:F24=""Fail""),{""Section 1 — Content"&""",""—"",""—"",""No issues found in this section"","""","""",""""}),IFERROR(FILTER(HSTACK(ARRAYFORMULA(IF(ROW(Design!B3:B29)-ROW(Design!B3)+1>0,""Section 2 — Design"","""")),Design!B3:B29,Design!C3:C29,Design!D3:D29,Design!E3:E29,Design!F3:F29,Design!G3:G"&"29),Design!F3:F29=""Fail""),{""Section 2 — Design"",""—"",""—"",""No issues found in this section"","""","""",""""}),IFERROR(FILTER(HSTACK(ARRAYFORMULA(IF(ROW(Development!B3:B28)-ROW(Development!B3)+1>0,""Section 3 — Development"","""")),Development!B3:B2"&"8,Development!C3:C28,Development!D3:D28,Development!E3:E28,Development!F3:F28,Development!G3:G28),Development!F3:F28=""Fail""),{""Section 3 — Development"",""—"",""—"",""No issues found in this section"","""","""",""""}),IFERROR(FILTER(HSTACK(ARRAYFORMULA"&"(IF(ROW(QA_Keyboard!B3:B14)-ROW(QA_Keyboard!B3)+1>0,""Section 4 — QA: Keyboard"","""")),QA_Keyboard!B3:B14,QA_Keyboard!C3:C14,QA_Keyboard!D3:D14,QA_Keyboard!E3:E14,QA_Keyboard!F3:F14,QA_Keyboard!G3:G14),QA_Keyboard!F3:F14=""Fail""),{""Section 4 — QA: Keyb"&"oard"",""—"",""—"",""No issues found in this section"","""","""",""""}),IFERROR(FILTER(HSTACK(ARRAYFORMULA(IF(ROW(QA_Forms!B3:B15)-ROW(QA_Forms!B3)+1>0,""Section 5 — QA: Forms & Input"","""")),QA_Forms!B3:B15,QA_Forms!C3:C15,QA_Forms!D3:D15,QA_Forms!E3:E1"&"5,QA_Forms!F3:F15,QA_Forms!G3:G15),QA_Forms!F3:F15=""Fail""),{""Section 5 — QA: Forms & Input"",""—"",""—"",""No issues found in this section"","""","""",""""}),IFERROR(FILTER(HSTACK(ARRAYFORMULA(IF(ROW(QA_Colour!B3:B8)-ROW(QA_Colour!B3)+1>0,""Section 6 —"&" QA: Colour & Contrast"","""")),QA_Colour!B3:B8,QA_Colour!C3:C8,QA_Colour!D3:D8,QA_Colour!E3:E8,QA_Colour!F3:F8,QA_Colour!G3:G8),QA_Colour!F3:F8=""Fail""),{""Section 6 — QA: Colour & Contrast"",""—"",""—"",""No issues found in this section"","""","""","""&"""}),IFERROR(FILTER(HSTACK(ARRAYFORMULA(IF(ROW(QA_ScreenReader!B3:B15)-ROW(QA_ScreenReader!B3)+1>0,""Section 7 — QA: Screen Reader"","""")),QA_ScreenReader!B3:B15,QA_ScreenReader!C3:C15,QA_ScreenReader!D3:D15,QA_ScreenReader!E3:E15,QA_ScreenReader!F3:F15,"&"QA_ScreenReader!G3:G15),QA_ScreenReader!F3:F15=""Fail""),{""Section 7 — QA: Screen Reader"",""—"",""—"",""No issues found in this section"","""","""",""""}),IFERROR(FILTER(HSTACK(ARRAYFORMULA(IF(ROW(QA_Media!B3:B16)-ROW(QA_Media!B3)+1>0,""Section 8 — QA: "&"Media"","""")),QA_Media!B3:B16,QA_Media!C3:C16,QA_Media!D3:D16,QA_Media!E3:E16,QA_Media!F3:F16,QA_Media!G3:G16),QA_Media!F3:F16=""Fail""),{""Section 8 — QA: Media"",""—"",""—"",""No issues found in this section"","""","""",""""}))"),"Section 1 — Content") -> Section 1 — Content | B8: =IFERROR(__xludf.DUMMYFUNCTION("""COMPUTED_VALUE"""),"1.1.1") -> 1.1.1 | C8: =IFERROR(__xludf.DUMMYFUNCTION("""COMPUTED_VALUE"""),"A") -> A | D8: =IFERROR(__xludf.DUMMYFUNCTION("""COMPUTED_VALUE"""),"Images have meaningful alternative text (or null alt if decorative)") -> Images have meaningful alternative text (or null alt if decorative) | E8: =IFERROR(__xludf.DUMMYFUNCTION("""COMPUTED_VALUE"""),"Content") -> Content | F8: =IFERROR(__xludf.DUMMYFUNCTION("""COMPUTED_VALUE"""),"Fail") -> Fail | G8: =IFERROR(__xludf.DUMMYFUNCTION("""COMPUTED_VALUE"""),"Illustrations missing alt tags (Wellbeing Pulse pages, Get involved pages) and Wellbeing Pulse cover image. All images are decorative and therefore low priority.") -> Illustrations missing alt tags (Wellbeing Pulse pages, Get involved pages) and Wellbeing Pulse cover image. All images are decorative and therefore low priority.
A9: =IFERROR(__xludf.DUMMYFUNCTION("""COMPUTED_VALUE"""),"Section 1 — Content") -> Section 1 — Content | B9: =IFERROR(__xludf.DUMMYFUNCTION("""COMPUTED_VALUE"""),"1.2.2") -> 1.2.2 | C9: =IFERROR(__xludf.DUMMYFUNCTION("""COMPUTED_VALUE"""),"A") -> A | D9: =IFERROR(__xludf.DUMMYFUNCTION("""COMPUTED_VALUE"""),"Captions provided for pre-recorded video with audio") -> Captions provided for pre-recorded video with audio | E9: =IFERROR(__xludf.DUMMYFUNCTION("""COMPUTED_VALUE"""),"Content") -> Content | F9: =IFERROR(__xludf.DUMMYFUNCTION("""COMPUTED_VALUE"""),"Fail") -> Fail | G9: =IFERROR(__xludf.DUMMYFUNCTION("""COMPUTED_VALUE"""),"Client stories videos missing captions") -> Client stories videos missing captions
A10: =IFERROR(__xludf.DUMMYFUNCTION("""COMPUTED_VALUE"""),"Section 1 — Content") -> Section 1 — Content | B10: =IFERROR(__xludf.DUMMYFUNCTION("""COMPUTED_VALUE"""),"1.2.5") -> 1.2.5 | C10: =IFERROR(__xludf.DUMMYFUNCTION("""COMPUTED_VALUE"""),"AA") -> AA | D10: =IFERROR(__xludf.DUMMYFUNCTION("""COMPUTED_VALUE"""),"Audio descriptions provided for pre-recorded video") -> Audio descriptions provided for pre-recorded video | E10: =IFERROR(__xludf.DUMMYFUNCTION("""COMPUTED_VALUE"""),"Content") -> Content | F10: =IFERROR(__xludf.DUMMYFUNCTION("""COMPUTED_VALUE"""),"Fail") -> Fail | G10: =IFERROR(__xludf.DUMMYFUNCTION("""COMPUTED_VALUE"""),"Client stories videos missing audio descriptions") -> Client stories videos missing audio descriptions
A11: =IFERROR(__xludf.DUMMYFUNCTION("""COMPUTED_VALUE"""),"Section 1 — Content") -> Section 1 — Content | B11: =IFERROR(__xludf.DUMMYFUNCTION("""COMPUTED_VALUE"""),"2.4.4") -> 2.4.4 | C11: =IFERROR(__xludf.DUMMYFUNCTION("""COMPUTED_VALUE"""),"A") -> A | D11: =IFERROR(__xludf.DUMMYFUNCTION("""COMPUTED_VALUE"""),"Ambiguous link text avoided; link purpose clear from link text alone") -> Ambiguous link text avoided; link purpose clear from link text alone | E11: =IFERROR(__xludf.DUMMYFUNCTION("""COMPUTED_VALUE"""),"Content") -> Content | F11: =IFERROR(__xludf.DUMMYFUNCTION("""COMPUTED_VALUE"""),"Fail") -> Fail | G11: =IFERROR(__xludf.DUMMYFUNCTION("""COMPUTED_VALUE"""),"""Tell me more, learn more, show me more"" links on homepage should be more descriptive e.g. ""Learn more about us, Read Daisy's story, Show me more client stories""") -> "Tell me more, learn more, show me more" links on homepage should be more descriptive e.g. "Learn more about us, Read Daisy's story, Show me more client stories"
A12: =IFERROR(__xludf.DUMMYFUNCTION("""COMPUTED_VALUE"""),"Section 1 — Content") -> Section 1 — Content | B12: =IFERROR(__xludf.DUMMYFUNCTION("""COMPUTED_VALUE"""),"3.2.4") -> 3.2.4 | C12: =IFERROR(__xludf.DUMMYFUNCTION("""COMPUTED_VALUE"""),"AA") -> AA | D12: =IFERROR(__xludf.DUMMYFUNCTION("""COMPUTED_VALUE"""),"Terminology for functionality is used consistently across the service") -> Terminology for functionality is used consistently across the service | E12: =IFERROR(__xludf.DUMMYFUNCTION("""COMPUTED_VALUE"""),"Content") -> Content | F12: =IFERROR(__xludf.DUMMYFUNCTION("""COMPUTED_VALUE"""),"Fail") -> Fail | G12: =IFERROR(__xludf.DUMMYFUNCTION("""COMPUTED_VALUE"""),"Form submission buttons vary between Submit and Sign up now/Sign up for webinar") -> Form submission buttons vary between Submit and Sign up now/Sign up for webinar
A13: =IFERROR(__xludf.DUMMYFUNCTION("""COMPUTED_VALUE"""),"Section 1 — Content") -> Section 1 — Content | B13: =IFERROR(__xludf.DUMMYFUNCTION("""COMPUTED_VALUE"""),"3.1.5") -> 3.1.5 | C13: =IFERROR(__xludf.DUMMYFUNCTION("""COMPUTED_VALUE"""),"AAA") -> AAA | D13: =IFERROR(__xludf.DUMMYFUNCTION("""COMPUTED_VALUE"""),"Content is written at an appropriate reading level (see webfx.com/tools/read-able/)") -> Content is written at an appropriate reading level (see webfx.com/tools/read-able/) | E13: =IFERROR(__xludf.DUMMYFUNCTION("""COMPUTED_VALUE"""),"Content") -> Content | F13: =IFERROR(__xludf.DUMMYFUNCTION("""COMPUTED_VALUE"""),"Fail") -> Fail | G13: =IFERROR(__xludf.DUMMYFUNCTION("""COMPUTED_VALUE"""),"Score of 40.5") -> Score of 40.5
A14: =IFERROR(__xludf.DUMMYFUNCTION("""COMPUTED_VALUE"""),"Section 2 — Design") -> Section 2 — Design | B14: =IFERROR(__xludf.DUMMYFUNCTION("""COMPUTED_VALUE"""),"2.4.7") -> 2.4.7 | C14: =IFERROR(__xludf.DUMMYFUNCTION("""COMPUTED_VALUE"""),"AA") -> AA | D14: =IFERROR(__xludf.DUMMYFUNCTION("""COMPUTED_VALUE"""),"Keyboard focus location is visually obvious at all times") -> Keyboard focus location is visually obvious at all times | E14: =IFERROR(__xludf.DUMMYFUNCTION("""COMPUTED_VALUE"""),"Dev") -> Dev | F14: =IFERROR(__xludf.DUMMYFUNCTION("""COMPUTED_VALUE"""),"Fail") -> Fail | G14: =IFERROR(__xludf.DUMMYFUNCTION("""COMPUTED_VALUE"""),"Keyboard focus not visible on video player (client story pages), webinar filter, multiple column fields on donate form, radio buttons on sign up form/webinar forms") -> Keyboard focus not visible on video player (client story pages), webinar filter, multiple column fields on donate form, radio buttons on sign up form/webinar forms
A15: =IFERROR(__xludf.DUMMYFUNCTION("""COMPUTED_VALUE"""),"Section 2 — Design") -> Section 2 — Design | B15: =IFERROR(__xludf.DUMMYFUNCTION("""COMPUTED_VALUE"""),"2.4.11") -> 2.4.11 | C15: =IFERROR(__xludf.DUMMYFUNCTION("""COMPUTED_VALUE"""),"AA") -> AA | D15: =IFERROR(__xludf.DUMMYFUNCTION("""COMPUTED_VALUE"""),"Focused component is not hidden or obscured by other content") -> Focused component is not hidden or obscured by other content | E15: =IFERROR(__xludf.DUMMYFUNCTION("""COMPUTED_VALUE"""),"Dev") -> Dev | F15: =IFERROR(__xludf.DUMMYFUNCTION("""COMPUTED_VALUE"""),"Fail") -> Fail | G15: =IFERROR(__xludf.DUMMYFUNCTION("""COMPUTED_VALUE"""),"Focus indicator is not visible on elements within a dropdown that is not expanded (guide pages) Focus indicator slightly obscured on homepage support dropdown") -> Focus indicator is not visible on elements within a dropdown that is not expanded (guide pages) Focus indicator slightly obscured on homepage support dropdown
A16: =IFERROR(__xludf.DUMMYFUNCTION("""COMPUTED_VALUE"""),"Section 2 — Design") -> Section 2 — Design | B16: =IFERROR(__xludf.DUMMYFUNCTION("""COMPUTED_VALUE"""),"2.4.13") -> 2.4.13 | C16: =IFERROR(__xludf.DUMMYFUNCTION("""COMPUTED_VALUE"""),"AAA") -> AAA | D16: =IFERROR(__xludf.DUMMYFUNCTION("""COMPUTED_VALUE"""),"Focus indicator has sufficient thickness and colour contrast") -> Focus indicator has sufficient thickness and colour contrast | E16: =IFERROR(__xludf.DUMMYFUNCTION("""COMPUTED_VALUE"""),"Dev / Designer") -> Dev / Designer | F16: =IFERROR(__xludf.DUMMYFUNCTION("""COMPUTED_VALUE"""),"Fail") -> Fail | G16: =IFERROR(__xludf.DUMMYFUNCTION("""COMPUTED_VALUE"""),"Focus indicator is 1px, should be minimum 2px. Blue focus indicator does not meet colour contrast against purple, but extra white outline appears on this background.") -> Focus indicator is 1px, should be minimum 2px. Blue focus indicator does not meet colour contrast against purple, but extra white outline appears on this background.
A17: =IFERROR(__xludf.DUMMYFUNCTION("""COMPUTED_VALUE"""),"Section 2 — Design") -> Section 2 — Design | B17: =IFERROR(__xludf.DUMMYFUNCTION("""COMPUTED_VALUE"""),"2.5.5") -> 2.5.5 | C17: =IFERROR(__xludf.DUMMYFUNCTION("""COMPUTED_VALUE"""),"AAA") -> AAA | D17: =IFERROR(__xludf.DUMMYFUNCTION("""COMPUTED_VALUE"""),"Touch targets are at least 44×44px") -> Touch targets are at least 44×44px | E17: =IFERROR(__xludf.DUMMYFUNCTION("""COMPUTED_VALUE"""),"Designer") -> Designer | F17: =IFERROR(__xludf.DUMMYFUNCTION("""COMPUTED_VALUE"""),"Fail") -> Fail | G17: =IFERROR(__xludf.DUMMYFUNCTION("""COMPUTED_VALUE"""),"Carousel buttons, social footer icons 40x40px, buttons 42px tall") -> Carousel buttons, social footer icons 40x40px, buttons 42px tall
A18: =IFERROR(__xludf.DUMMYFUNCTION("""COMPUTED_VALUE"""),"Section 3 — Development") -> Section 3 — Development | B18: =IFERROR(__xludf.DUMMYFUNCTION("""COMPUTED_VALUE"""),"1.4.13") -> 1.4.13 | C18: =IFERROR(__xludf.DUMMYFUNCTION("""COMPUTED_VALUE"""),"AA") -> AA | D18: =IFERROR(__xludf.DUMMYFUNCTION("""COMPUTED_VALUE"""),"Popovers on hover/focus can be dismissed via keyboard without moving focus") -> Popovers on hover/focus can be dismissed via keyboard without moving focus | E18: =IFERROR(__xludf.DUMMYFUNCTION("""COMPUTED_VALUE"""),"Developer") -> Developer | F18: =IFERROR(__xludf.DUMMYFUNCTION("""COMPUTED_VALUE"""),"Fail") -> Fail | G18: =IFERROR(__xludf.DUMMYFUNCTION("""COMPUTED_VALUE"""),"Popover is dimissed with tab not esc. Cannot tab through elements within the popover as tab triggers it to close") -> Popover is dimissed with tab not esc. Cannot tab through elements within the popover as tab triggers it to close
A19: =IFERROR(__xludf.DUMMYFUNCTION("""COMPUTED_VALUE"""),"Section 3 — Development") -> Section 3 — Development | B19: =IFERROR(__xludf.DUMMYFUNCTION("""COMPUTED_VALUE"""),"2.1.1") -> 2.1.1 | C19: =IFERROR(__xludf.DUMMYFUNCTION("""COMPUTED_VALUE"""),"A") -> A | D19: =IFERROR(__xludf.DUMMYFUNCTION("""COMPUTED_VALUE"""),"All functionality is operable using the keyboard alone") -> All functionality is operable using the keyboard alone | E19: =IFERROR(__xludf.DUMMYFUNCTION("""COMPUTED_VALUE"""),"Developer") -> Developer | F19: =IFERROR(__xludf.DUMMYFUNCTION("""COMPUTED_VALUE"""),"Fail") -> Fail | G19: =IFERROR(__xludf.DUMMYFUNCTION("""COMPUTED_VALUE"""),"Cannot tab elements within nav popover") -> Cannot tab elements within nav popover
A20: =IFERROR(__xludf.DUMMYFUNCTION("""COMPUTED_VALUE"""),"Section 3 — Development") -> Section 3 — Development | B20: =IFERROR(__xludf.DUMMYFUNCTION("""COMPUTED_VALUE"""),"2.3.3") -> 2.3.3 | C20: =IFERROR(__xludf.DUMMYFUNCTION("""COMPUTED_VALUE"""),"AAA") -> AAA | D20: =IFERROR(__xludf.DUMMYFUNCTION("""COMPUTED_VALUE"""),"Animations respect the prefers-reduced-motion OS/browser setting") -> Animations respect the prefers-reduced-motion OS/browser setting | E20: =IFERROR(__xludf.DUMMYFUNCTION("""COMPUTED_VALUE"""),"Developer") -> Developer | F20: =IFERROR(__xludf.DUMMYFUNCTION("""COMPUTED_VALUE"""),"Fail") -> Fail | G20: =IFERROR(__xludf.DUMMYFUNCTION("""COMPUTED_VALUE"""),"Animations with substantial movement should be disabled on interaction. Examples include the circular icons on the homepage and the slideup animation associated with the menu on desktop.") -> Animations with substantial movement should be disabled on interaction. Examples include the circular icons on the homepage and the slideup animation associated with the menu on desktop.
A21: =IFERROR(__xludf.DUMMYFUNCTION("""COMPUTED_VALUE"""),"Section 3 — Development") -> Section 3 — Development | B21: =IFERROR(__xludf.DUMMYFUNCTION("""COMPUTED_VALUE"""),"4.1.1") -> 4.1.1 | C21: =IFERROR(__xludf.DUMMYFUNCTION("""COMPUTED_VALUE"""),"A") -> A | D21: =IFERROR(__xludf.DUMMYFUNCTION("""COMPUTED_VALUE"""),"HTML validates with no parsing errors that affect accessibility") -> HTML validates with no parsing errors that affect accessibility | E21: =IFERROR(__xludf.DUMMYFUNCTION("""COMPUTED_VALUE"""),"Developer") -> Developer | F21: =IFERROR(__xludf.DUMMYFUNCTION("""COMPUTED_VALUE"""),"Fail") -> Fail | G21: =IFERROR(__xludf.DUMMYFUNCTION("""COMPUTED_VALUE"""),"Donation form fails validation on multiple empty heading tags and autocomplete tags being added to hidden elements. Report.") -> Donation form fails validation on multiple empty heading tags and autocomplete tags being added to hidden elements. Report.
A22: =IFERROR(__xludf.DUMMYFUNCTION("""COMPUTED_VALUE"""),"Section 3 — Development") -> Section 3 — Development | B22: =IFERROR(__xludf.DUMMYFUNCTION("""COMPUTED_VALUE"""),"4.1.3") -> 4.1.3 | C22: =IFERROR(__xludf.DUMMYFUNCTION("""COMPUTED_VALUE"""),"AA") -> AA | D22: =IFERROR(__xludf.DUMMYFUNCTION("""COMPUTED_VALUE"""),"Status messages (e.g. alerts, toasts) are announced by screen readers") -> Status messages (e.g. alerts, toasts) are announced by screen readers | E22: =IFERROR(__xludf.DUMMYFUNCTION("""COMPUTED_VALUE"""),"Developer") -> Developer | F22: =IFERROR(__xludf.DUMMYFUNCTION("""COMPUTED_VALUE"""),"Fail") -> Fail | G22: =IFERROR(__xludf.DUMMYFUNCTION("""COMPUTED_VALUE"""),"Error message on donate form announced as ""undefined"" after failed form submission") -> Error message on donate form announced as "undefined" after failed form submission
A23: =IFERROR(__xludf.DUMMYFUNCTION("""COMPUTED_VALUE"""),"Section 4 — QA: Keyboard") -> Section 4 — QA: Keyboard | B23: =IFERROR(__xludf.DUMMYFUNCTION("""COMPUTED_VALUE"""),"2.1.1") -> 2.1.1 | C23: =IFERROR(__xludf.DUMMYFUNCTION("""COMPUTED_VALUE"""),"A") -> A | D23: =IFERROR(__xludf.DUMMYFUNCTION("""COMPUTED_VALUE"""),"Tab through all interactive elements — nothing is skipped") -> Tab through all interactive elements — nothing is skipped | E23: =IFERROR(__xludf.DUMMYFUNCTION("""COMPUTED_VALUE"""),"QA / Developer") -> QA / Developer | F23: =IFERROR(__xludf.DUMMYFUNCTION("""COMPUTED_VALUE"""),"Fail") -> Fail | G23: =IFERROR(__xludf.DUMMYFUNCTION("""COMPUTED_VALUE"""),"Sub navigation on desktop is difficult to tab through, list items are missed.") -> Sub navigation on desktop is difficult to tab through, list items are missed.
A24: =IFERROR(__xludf.DUMMYFUNCTION("""COMPUTED_VALUE"""),"Section 4 — QA: Keyboard") -> Section 4 — QA: Keyboard | B24: =IFERROR(__xludf.DUMMYFUNCTION("""COMPUTED_VALUE"""),"2.1.1") -> 2.1.1 | C24: =IFERROR(__xludf.DUMMYFUNCTION("""COMPUTED_VALUE"""),"A") -> A | D24: =IFERROR(__xludf.DUMMYFUNCTION("""COMPUTED_VALUE"""),"All buttons, links, and controls can be activated with Enter or Space") -> All buttons, links, and controls can be activated with Enter or Space | E24: =IFERROR(__xludf.DUMMYFUNCTION("""COMPUTED_VALUE"""),"QA / Developer") -> QA / Developer | F24: =IFERROR(__xludf.DUMMYFUNCTION("""COMPUTED_VALUE"""),"Fail") -> Fail | G24: =IFERROR(__xludf.DUMMYFUNCTION("""COMPUTED_VALUE"""),"Video play button does not activate") -> Video play button does not activate
A25: =IFERROR(__xludf.DUMMYFUNCTION("""COMPUTED_VALUE"""),"Section 4 — QA: Keyboard") -> Section 4 — QA: Keyboard | B25: =IFERROR(__xludf.DUMMYFUNCTION("""COMPUTED_VALUE"""),"2.4.7") -> 2.4.7 | C25: =IFERROR(__xludf.DUMMYFUNCTION("""COMPUTED_VALUE"""),"AA") -> AA | D25: =IFERROR(__xludf.DUMMYFUNCTION("""COMPUTED_VALUE"""),"Focus indicator is always visible (check all states: default, hover, active)") -> Focus indicator is always visible (check all states: default, hover, active) | E25: =IFERROR(__xludf.DUMMYFUNCTION("""COMPUTED_VALUE"""),"QA / Designer") -> QA / Designer | F25: =IFERROR(__xludf.DUMMYFUNCTION("""COMPUTED_VALUE"""),"Fail") -> Fail | G25: =IFERROR(__xludf.DUMMYFUNCTION("""COMPUTED_VALUE"""),"Keyboard focus not visible on video player (client story pages), webinar filter, multiple column fields on donate form, radio buttons on sign up form/webinar forms") -> Keyboard focus not visible on video player (client story pages), webinar filter, multiple column fields on donate form, radio buttons on sign up form/webinar forms
A26: =IFERROR(__xludf.DUMMYFUNCTION("""COMPUTED_VALUE"""),"Section 4 — QA: Keyboard") -> Section 4 — QA: Keyboard | B26: =IFERROR(__xludf.DUMMYFUNCTION("""COMPUTED_VALUE"""),"1.4.13") -> 1.4.13 | C26: =IFERROR(__xludf.DUMMYFUNCTION("""COMPUTED_VALUE"""),"AA") -> AA | D26: =IFERROR(__xludf.DUMMYFUNCTION("""COMPUTED_VALUE"""),"Content on hover/focus (tooltips, dropdowns) can be dismissed with Esc") -> Content on hover/focus (tooltips, dropdowns) can be dismissed with Esc | E26: =IFERROR(__xludf.DUMMYFUNCTION("""COMPUTED_VALUE"""),"QA / Developer") -> QA / Developer | F26: =IFERROR(__xludf.DUMMYFUNCTION("""COMPUTED_VALUE"""),"Fail") -> Fail | G26: =IFERROR(__xludf.DUMMYFUNCTION("""COMPUTED_VALUE"""),"Popover is dimissed with tab not esc. Cannot tab through elements within the popover as tab triggers it to close") -> Popover is dimissed with tab not esc. Cannot tab through elements within the popover as tab triggers it to close
A27: =IFERROR(__xludf.DUMMYFUNCTION("""COMPUTED_VALUE"""),"Section 4 — QA: Keyboard") -> Section 4 — QA: Keyboard | B27: =IFERROR(__xludf.DUMMYFUNCTION("""COMPUTED_VALUE"""),"—") -> — | C27: =IFERROR(__xludf.DUMMYFUNCTION("""COMPUTED_VALUE"""),"BP") -> BP | D27: =IFERROR(__xludf.DUMMYFUNCTION("""COMPUTED_VALUE"""),"Modal dialogs trap focus correctly and return focus on close") -> Modal dialogs trap focus correctly and return focus on close | E27: =IFERROR(__xludf.DUMMYFUNCTION("""COMPUTED_VALUE"""),"QA / Developer") -> QA / Developer | F27: =IFERROR(__xludf.DUMMYFUNCTION("""COMPUTED_VALUE"""),"Fail") -> Fail | G27: =IFERROR(__xludf.DUMMYFUNCTION("""COMPUTED_VALUE"""),"Nav popover doesn't trap focus, cannot tab through elements within the popover as tab triggers it to close and tab onto next nav item") -> Nav popover doesn't trap focus, cannot tab through elements within the popover as tab triggers it to close and tab onto next nav item
A28: =IFERROR(__xludf.DUMMYFUNCTION("""COMPUTED_VALUE"""),"Section 5 — QA: Forms & Input") -> Section 5 — QA: Forms & Input | B28: =IFERROR(__xludf.DUMMYFUNCTION("""COMPUTED_VALUE"""),"—") -> — | C28: =IFERROR(__xludf.DUMMYFUNCTION("""COMPUTED_VALUE"""),"BP") -> BP | D28: =IFERROR(__xludf.DUMMYFUNCTION("""COMPUTED_VALUE"""),"Success confirmation is announced to screen readers via ARIA live region") -> Success confirmation is announced to screen readers via ARIA live region | E28: =IFERROR(__xludf.DUMMYFUNCTION("""COMPUTED_VALUE"""),"QA / Developer") -> QA / Developer | F28: =IFERROR(__xludf.DUMMYFUNCTION("""COMPUTED_VALUE"""),"Fail") -> Fail | G28: =IFERROR(__xludf.DUMMYFUNCTION("""COMPUTED_VALUE"""),"Third party forms do not make use or ARIA live regions") -> Third party forms do not make use or ARIA live regions
A29: =IFERROR(__xludf.DUMMYFUNCTION("""COMPUTED_VALUE"""),"Section 6 — QA: Colour & Contrast") -> Section 6 — QA: Colour & Contrast | B29: =IFERROR(__xludf.DUMMYFUNCTION("""COMPUTED_VALUE"""),"—") -> — | C29: =IFERROR(__xludf.DUMMYFUNCTION("""COMPUTED_VALUE"""),"—") -> — | D29: =IFERROR(__xludf.DUMMYFUNCTION("""COMPUTED_VALUE"""),"No issues found in this section") -> No issues found in this section | E29: =IFERROR(__xludf.DUMMYFUNCTION("""COMPUTED_VALUE"""),"") | F29: =IFERROR(__xludf.DUMMYFUNCTION("""COMPUTED_VALUE"""),"") | G29: =IFERROR(__xludf.DUMMYFUNCTION("""COMPUTED_VALUE"""),"")
A30: =IFERROR(__xludf.DUMMYFUNCTION("""COMPUTED_VALUE"""),"Section 7 — QA: Screen Reader") -> Section 7 — QA: Screen Reader | B30: =IFERROR(__xludf.DUMMYFUNCTION("""COMPUTED_VALUE"""),"1.1.1") -> 1.1.1 | C30: =IFERROR(__xludf.DUMMYFUNCTION("""COMPUTED_VALUE"""),"A") -> A | D30: =IFERROR(__xludf.DUMMYFUNCTION("""COMPUTED_VALUE"""),"All meaningful images have descriptive alt text; decorative images have alt=""""") -> All meaningful images have descriptive alt text; decorative images have alt="" | E30: =IFERROR(__xludf.DUMMYFUNCTION("""COMPUTED_VALUE"""),"QA / Content") -> QA / Content | F30: =IFERROR(__xludf.DUMMYFUNCTION("""COMPUTED_VALUE"""),"Fail") -> Fail
A31: =IFERROR(__xludf.DUMMYFUNCTION("""COMPUTED_VALUE"""),"Section 7 — QA: Screen Reader") -> Section 7 — QA: Screen Reader | B31: =IFERROR(__xludf.DUMMYFUNCTION("""COMPUTED_VALUE"""),"2.4.4") -> 2.4.4 | C31: =IFERROR(__xludf.DUMMYFUNCTION("""COMPUTED_VALUE"""),"A") -> A | D31: =IFERROR(__xludf.DUMMYFUNCTION("""COMPUTED_VALUE"""),"All links and buttons have descriptive accessible names (not 'click here')") -> All links and buttons have descriptive accessible names (not 'click here') | E31: =IFERROR(__xludf.DUMMYFUNCTION("""COMPUTED_VALUE"""),"QA / Content") -> QA / Content | F31: =IFERROR(__xludf.DUMMYFUNCTION("""COMPUTED_VALUE"""),"Fail") -> Fail
A32: =IFERROR(__xludf.DUMMYFUNCTION("""COMPUTED_VALUE"""),"Section 7 — QA: Screen Reader") -> Section 7 — QA: Screen Reader | B32: =IFERROR(__xludf.DUMMYFUNCTION("""COMPUTED_VALUE"""),"4.1.3") -> 4.1.3 | C32: =IFERROR(__xludf.DUMMYFUNCTION("""COMPUTED_VALUE"""),"AA") -> AA | D32: =IFERROR(__xludf.DUMMYFUNCTION("""COMPUTED_VALUE"""),"Dynamic content updates (alerts, validation, status) are announced") -> Dynamic content updates (alerts, validation, status) are announced | E32: =IFERROR(__xludf.DUMMYFUNCTION("""COMPUTED_VALUE"""),"QA / Developer") -> QA / Developer | F32: =IFERROR(__xludf.DUMMYFUNCTION("""COMPUTED_VALUE"""),"Fail") -> Fail | G32: =IFERROR(__xludf.DUMMYFUNCTION("""COMPUTED_VALUE"""),"Error message on donate form announced as ""undefined"" after failed form submission") -> Error message on donate form announced as "undefined" after failed form submission
A33: =IFERROR(__xludf.DUMMYFUNCTION("""COMPUTED_VALUE"""),"Section 8 — QA: Media") -> Section 8 — QA: Media | B33: =IFERROR(__xludf.DUMMYFUNCTION("""COMPUTED_VALUE"""),"1.2.2") -> 1.2.2 | C33: =IFERROR(__xludf.DUMMYFUNCTION("""COMPUTED_VALUE"""),"A") -> A | D33: =IFERROR(__xludf.DUMMYFUNCTION("""COMPUTED_VALUE"""),"Pre-recorded video with audio has accurate captions") -> Pre-recorded video with audio has accurate captions | E33: =IFERROR(__xludf.DUMMYFUNCTION("""COMPUTED_VALUE"""),"Content") -> Content | F33: =IFERROR(__xludf.DUMMYFUNCTION("""COMPUTED_VALUE"""),"Fail") -> Fail | G33: =IFERROR(__xludf.DUMMYFUNCTION("""COMPUTED_VALUE"""),"Client stories videos missing captions") -> Client stories videos missing captions
A34: =IFERROR(__xludf.DUMMYFUNCTION("""COMPUTED_VALUE"""),"Section 8 — QA: Media") -> Section 8 — QA: Media | B34: =IFERROR(__xludf.DUMMYFUNCTION("""COMPUTED_VALUE"""),"1.2.3") -> 1.2.3 | C34: =IFERROR(__xludf.DUMMYFUNCTION("""COMPUTED_VALUE"""),"A") -> A | D34: =IFERROR(__xludf.DUMMYFUNCTION("""COMPUTED_VALUE"""),"Pre-recorded video has an audio description or full text alternative") -> Pre-recorded video has an audio description or full text alternative | E34: =IFERROR(__xludf.DUMMYFUNCTION("""COMPUTED_VALUE"""),"Content") -> Content | F34: =IFERROR(__xludf.DUMMYFUNCTION("""COMPUTED_VALUE"""),"Fail") -> Fail | G34: =IFERROR(__xludf.DUMMYFUNCTION("""COMPUTED_VALUE"""),"Client stories videos missing audio description") -> Client stories videos missing audio description
A35: =IFERROR(__xludf.DUMMYFUNCTION("""COMPUTED_VALUE"""),"Section 8 — QA: Media") -> Section 8 — QA: Media | B35: =IFERROR(__xludf.DUMMYFUNCTION("""COMPUTED_VALUE"""),"1.2.5") -> 1.2.5 | C35: =IFERROR(__xludf.DUMMYFUNCTION("""COMPUTED_VALUE"""),"AA") -> AA | D35: =IFERROR(__xludf.DUMMYFUNCTION("""COMPUTED_VALUE"""),"Pre-recorded video has a synchronised audio description track") -> Pre-recorded video has a synchronised audio description track | E35: =IFERROR(__xludf.DUMMYFUNCTION("""COMPUTED_VALUE"""),"Content") -> Content | F35: =IFERROR(__xludf.DUMMYFUNCTION("""COMPUTED_VALUE"""),"Fail") -> Fail | G35: =IFERROR(__xludf.DUMMYFUNCTION("""COMPUTED_VALUE"""),"Client stories videos missing audio description") -> Client stories videos missing audio description
A36: =IFERROR(__xludf.DUMMYFUNCTION("""COMPUTED_VALUE"""),"Section 8 — QA: Media") -> Section 8 — QA: Media | B36: =IFERROR(__xludf.DUMMYFUNCTION("""COMPUTED_VALUE"""),"—") -> — | C36: =IFERROR(__xludf.DUMMYFUNCTION("""COMPUTED_VALUE"""),"BP") -> BP | D36: =IFERROR(__xludf.DUMMYFUNCTION("""COMPUTED_VALUE"""),"Embedded video player is fully keyboard accessible") -> Embedded video player is fully keyboard accessible | E36: =IFERROR(__xludf.DUMMYFUNCTION("""COMPUTED_VALUE"""),"Developer") -> Developer | F36: =IFERROR(__xludf.DUMMYFUNCTION("""COMPUTED_VALUE"""),"Fail") -> Fail | G36: =IFERROR(__xludf.DUMMYFUNCTION("""COMPUTED_VALUE"""),"Cannot interact with keyboard") -> Cannot interact with keyboard

Sheet Content
A1: Section 1 — Content
A2: # | B2: WCAG Criterion | C2: Level | D2: Description / What to Check | E2: Owner | F2: Status | G2: Notes
A3: Text Alternatives & Media
A4: 1 | B4: 1.1.1 | C4: A | D4: Images have meaningful alternative text (or null alt if decorative) | E4: Content | F4: Fail | G4: Illustrations missing alt tags (Wellbeing Pulse pages, Get involved pages) and Wellbeing Pulse cover image. All images are decorative and therefore low priority.
A5: 2 | B5: 1.2.1 | C5: A | D5: Transcripts provided for audio-only content (podcasts, recordings) | E5: Content | F5: N/A
A6: 3 | B6: 1.2.1 | C6: A | D6: Visual-only video content has an audio or text equivalent | E6: Content | F6: N/A
A7: 4 | B7: 1.2.2 | C7: A | D7: Captions provided for pre-recorded video with audio | E7: Content | F7: Fail | G7: Client stories videos missing captions
A8: 5 | B8: 1.2.3 | C8: A | D8: Audio description or text alternative available for pre-recorded video that play a functional role | E8: Content | F8: N/A
A9: 6 | B9: 1.2.4 | C9: AA | D9: Captions provided for live video with audio (live stream content) | E9: Content | F9: N/A
A10: 7 | B10: 1.2.5 | C10: AA | D10: Audio descriptions provided for pre-recorded video | E10: Content | F10: Fail | G10: Client stories videos missing audio descriptions
A11: Presentation & Links
A12: 8 | B12: 1.3.3 | C12: A | D12: Instructions do not rely solely on shape, size, sound, location or orientation | E12: Content | F12: Pass
A13: 9 | B13: 1.4.5 | C13: AA | D13: Images of text are not used (logos excepted) | E13: Content | F13: Pass
A14: 10 | B14: 2.4.4 | C14: A | D14: Ambiguous link text avoided; link purpose clear from link text alone | E14: Content | F14: Fail | G14: "Tell me more, learn more, show me more" links on homepage should be more descriptive e.g. "Learn more about us, Read Daisy's story, Show me more client stories"
A15: 11 | B15: 2.4.6 | C15: AA | D15: Headings and labels clearly describe topic or purpose | E15: Content | F15: Pass
A16: Language & Errors
A17: 12 | B17: 3.1.1 | C17: A | D17: Language of page is set correctly on the html element | E17: Dev | F17: Pass
A18: 13 | B18: 3.1.2 | C18: AA | D18: Language changes within content are marked up with correct lang codes | E18: Content / Dev | F18: N/A
A19: 14 | B19: 3.2.4 | C19: AA | D19: Terminology for functionality is used consistently across the service | E19: Content | F19: Fail | G19: Form submission buttons vary between Submit and Sign up now/Sign up for webinar
A20: 15 | B20: 3.2.6 | C20: A | D20: Any help provided (e.g. FAQs, chat) is consistently positioned | E20: Content | F20: Pass
A21: 16 | B21: 3.3.1 | C21: A | D21: Errors are identified and described to the user in text, not colour alone | E21: Content | F21: Pass
A22: 17 | B22: 3.3.2 | C22: A | D22: Labels and instructions are visible and appropriate for all inputs | E22: Content | F22: Pass
A23: 18 | B23: 3.3.3 | C23: AA | D23: Error messages are useful and suggest valid corrections | E23: Content | F23: Pass
A24: 19 | B24: 3.1.5 | C24: AAA | D24: Content is written at an appropriate reading level (see webfx.com/tools/read-able/) | E24: Content | F24: Fail | G24: Score of 40.5

Sheet Design
A1: Section 2 — Design
A2: # | B2: WCAG Criterion | C2: Level | D2: Description / What to Check | E2: Owner | F2: Status | G2: Notes
A3: Colour & Contrast
A4: 1 | B4: 1.4.1 | C4: A | D4: Colour is not the sole means of conveying information | E4: Designer | F4: Pass
A5: 2 | B5: 1.4.3 | C5: AA | D5: Text contrast meets minimum 4.5:1 (3:1 for large text) | E5: Designer | F5: Pass
A6: 3 | B6: 1.4.11 | C6: AA | D6: Non-text UI components and focus styles meet 3:1 contrast ratio | E6: Designer | F6: Pass
A7: Motion & Timing
A8: 4 | B8: 1.4.2 | C8: A | D8: Audio does not play automatically | E8: Dev | F8: Pass | G8: No autoplay videos
A9: 5 | B9: 2.2.1 | C9: A | D9: Session timeouts can be extended or turned off | E9: Dev | F9: N/A | G9: No time sensitive functionality
A10: 6 | B10: 2.2.2 | C10: A | D10: Moving, blinking or auto-updating content can be paused, stopped or hidden | E10: Dev | F10: N/A | G10: No carousels or moving content
A11: 7 | B11: 2.3.1 | C11: A | D11: Content does not flash more than 3 times per second | E11: Dev | F11: Pass
A12: Navigation & Focus
A13: 8 | B13: 2.4.1 | C13: A | D13: Skip navigation mechanism provided to reach main content | E13: Dev | F13: Pass
A14: 9 | B14: 2.4.3 | C14: A | D14: Focus order is logical, intuitive and matches visual layout | E14: Dev | F14: Pass
A15: 10 | B15: 2.4.5 | C15: AA | D15: Multiple ways to locate a page are available (search, sitemap, nav) | E15: Designer | F15: Pass | G15: Search and nav
A16: 11 | B16: 2.4.7 | C16: AA | D16: Keyboard focus location is visually obvious at all times | E16: Dev | F16: Fail | G16: Keyboard focus not visible on video player (client story pages), webinar filter, multiple column fields on donate form, radio buttons on sign up form/webinar forms
A17: 12 | B17: 2.4.11 | C17: AA | D17: Focused component is not hidden or obscured by other content | E17: Dev | F17: Fail | G17: Focus indicator is not visible on elements within a dropdown that is not expanded (guide pages) Focus indicator slightly obscured on homepage support dropdown
A18: 13 | B18: 2.4.13 | C18: AAA | D18: Focus indicator has sufficient thickness and colour contrast | E18: Dev / Designer | F18: Fail | G18: Focus indicator is 1px, should be minimum 2px. Blue focus indicator does not meet colour contrast against purple, but extra white outline appears on this background.
A19: Touch & Input
A20: 14 | B20: 2.5.1 | C20: A | D20: All functionality works without touch-only gestures; alternatives provided | E20: Dev | F20: Pass
A21: 15 | B21: 2.5.5 | C21: AAA | D21: Touch targets are at least 44×44px | E21: Designer | F21: Fail | G21: Carousel buttons, social footer icons 40x40px, buttons 42px tall
A22: 16 | B22: 2.5.7 | C22: AA | D22: Dragging interactions have a single-pointer alternative | E22: Designer | F22: Pass
A23: 17 | B23: 2.5.8 | C23: AA | D23: Interactive components meet minimum target size requirements (24px × 24px) | E23: Designer / Dev | F23: Pass
A24: Consistency & Forms
A25: 18 | B25: 3.2.1 | C25: A | D25: Focus landing on an element does not trigger a context change | E25: Dev | F25: Pass
A26: 19 | B26: 3.2.3 | C26: AA | D26: Navigation is consistent across pages in order and labelling | E26: Designer / Content | F26: Pass
A27: 20 | B27: 3.3.4 | C27: AA | D27: Legal or financial actions can be reversed, reviewed or confirmed | E27: Designer | F27: N/A | G27: Financial actions on third party site (Stripe) not tested. No financial/legal actions on BWC site.
A28: 21 | B28: 3.3.7 | C28: A | D28: Users are not required to re-enter information already provided | E28: Designer / Dev | F28: Pass
A29: 22 | B29: 3.3.8 | C29: AA | D29: Authentication does not require a cognitive function test | E29: Dev | F29: Pass

Sheet Development
A1: Section 3 — Development
A2: # | B2: WCAG Criterion | C2: Level | D2: Description / What to Check | E2: Owner | F2: Status | G2: Notes
A3: Semantics & Structure
A4: 1 | B4: 1.3.1 | C4: A | D4: Font icons are not used; SVG or image icons with alt text used instead | E4: Developer | F4: Pass
A5: 2 | B5: 1.3.1 | C5: A | D5: Form code is semantically correct (labels, fieldsets, legends) | E5: Developer | F5: Pass | G5: Forms created by pixelfridge include correct labels and legends.
A6: 3 | B6: 1.3.1 | C6: A | D6: HTML structure uses correct landmarks, headings, lists, and data tables | E6: Developer | F6: Pass | G6: The "How can we support you?" interactive form area and the newsletter sign-up container lack clear sectioning landmarks (like an <aside> or a <section> tag paired with an aria-labelledby). Wrapping these distinct sections in programmatic landmarks would make page scanning much smoother for screen reader users.
A7: 4 | B7: 1.3.1 | C7: A | D7: Inline CSS is not used for visual-only styles that carry meaning | E7: Developer | F7: Pass | G7: Where graphical elements or color are used alone to convey information, accompanying screen reader text or clear labels are provided.
A8: 5 | B8: 1.3.2 | C8: A | D8: Content order in the DOM is logical and mirrors the visual sequence | E8: Developer | F8: Pass | G8: JS is not used to manipulate the DOM, order reflects visual sequence
A9: 6 | B9: 1.3.5 | C9: AA | D9: Autocomplete attributes applied correctly to relevant input fields | E9: Developer | F9: Pass | G9: Autocomplete present on some but not all fields (varies by form). Those present are correct
A10: Text & Zoom
A11: 7 | B11: 1.4.4 | C11: AA | D11: Text can be resized to 200% without loss of content or functionality | E11: Developer | F11: Pass
A12: 8 | B12: 1.4.10 | C12: AA | D12: Content reflows at 400% zoom without horizontal scrolling or loss | E12: Developer | F12: Pass
A13: 9 | B13: 1.4.13 | C13: AA | D13: Popovers on hover/focus can be dismissed via keyboard without moving focus | E13: Developer | F13: Fail | G13: Popover is dimissed with tab not esc. Cannot tab through elements within the popover as tab triggers it to close
A14: Keyboard & Interaction
A15: 10 | B15: 2.1.1 | C15: A | D15: All functionality is operable using the keyboard alone | E15: Developer | F15: Fail | G15: Cannot tab elements within nav popover
A16: 11 | B16: 2.1.2 | C16: A | D16: Keyboard focus is never trapped (except intentional modal dialogs) | E16: Developer | F16: Pass
A17: 12 | B17: 2.3.3 | C17: AAA | D17: Animations respect the prefers-reduced-motion OS/browser setting | E17: Developer | F17: Fail | G17: Animations with substantial movement should be disabled on interaction. Examples include the circular icons on the homepage and the slideup animation associated with the menu on desktop.
A18: 13 | B18: 2.5.2 | C18: A | D18: Actions are triggered on pointer up (not down) unless cancellable | E18: Developer | F18: Pass
A19: 14 | B19: 2.5.3 | C19: A | D19: Visible labels are included in the accessible name of controls | E19: Developer | F19: Pass
A20: 15 | B20: 3.2.1 | C20: A | D20: No context changes triggered by element receiving focus | E20: Developer | F20: Pass
A21: ARIA & Validation
A22: 16 | B22: 4.1.1 | C22: A | D22: HTML validates with no parsing errors that affect accessibility | E22: Developer | F22: Fail | G22: Donation form fails validation on multiple empty heading tags and autocomplete tags being added to hidden elements. Report.
A23: 17 | B23: 4.1.2 | C23: A | D23: All UI components have correct name, role and value exposed to AT | E23: Developer | F23: Pass | G23: All buttons have clear, descriptive labels. For buttons without visible text labels, title attributes and aria-label attributes have been provided to ensure accessibility.
A24: 18 | B24: 4.1.2 | C24: A | D24: Custom controls use WAI-ARIA correctly and are fully keyboard operable | E24: Developer | F24: N/A
A25: 19 | B25: 4.1.3 | C25: AA | D25: Status messages (e.g. alerts, toasts) are announced by screen readers | E25: Developer | F25: Fail | G25: Error message on donate form announced as "undefined" after failed form submission
A26: Best Practice
A27: 20 | B27: — | C27: BP | D27: Windows High Contrast Mode does not break the interface | E27: Developer | F27: Pass | G27: Testing in high contrast and website is full usable without any issues.
A28: 21 | B28: — | C28: BP | D28: HTML lang attribute set on root element and language changes inline | E28: Developer | F28: Pass

Sheet QA_Keyboard
A1: Section 4 — QA: Keyboard
A2: # | B2: WCAG Criterion | C2: Level | D2: Description / What to Check | E2: Owner | F2: Status | G2: Notes
A3: Keyboard Navigation
A4: 1 | B4: 2.1.1 | C4: A | D4: Tab through all interactive elements — nothing is skipped | E4: QA / Developer | F4: Fail | G4: Sub navigation on desktop is difficult to tab through, list items are missed.
A5: 2 | B5: 2.1.1 | C5: A | D5: All buttons, links, and controls can be activated with Enter or Space | E5: QA / Developer | F5: Fail | G5: Video play button does not activate
A6: 3 | B6: 2.1.2 | C6: A | D6: Focus never becomes trapped outside of intentional modal dialogs | E6: QA / Developer | F6: Pass
A7: 4 | B7: 2.4.3 | C7: A | D7: Focus order follows the logical visual reading sequence | E7: QA / Developer | F7: Pass
A8: 5 | B8: 2.4.7 | C8: AA | D8: Focus indicator is always visible (check all states: default, hover, active) | E8: QA / Designer | F8: Fail | G8: Keyboard focus not visible on video player (client story pages), webinar filter, multiple column fields on donate form, radio buttons on sign up form/webinar forms
A9: 6 | B9: 2.4.11 | C9: AA | D9: Focused element is not obscured by sticky headers, banners or overlays | E9: QA / Developer | F9: Pass
A10: 7 | B10: 1.4.13 | C10: AA | D10: Content on hover/focus (tooltips, dropdowns) can be dismissed with Esc | E10: QA / Developer | F10: Fail | G10: Popover is dimissed with tab not esc. Cannot tab through elements within the popover as tab triggers it to close
A11: Best Practice
A12: 8 | B12: — | C12: BP | D12: Skip to main content link appears on first Tab keypress | E12: QA / Developer | F12: Pass
A13: 9 | B13: — | C13: BP | D13: Modal dialogs trap focus correctly and return focus on close | E13: QA / Developer | F13: Fail | G13: Nav popover doesn't trap focus, cannot tab through elements within the popover as tab triggers it to close and tab onto next nav item
A14: 10 | B14: — | C14: BP | D14: Custom components (carousels, accordions) follow ARIA design patterns | E14: QA / Developer | F14: Pass | G14: Accordions have clear aria-labels including open & close labels

Sheet QA_Forms
A1: Section 5 — QA: Forms & Input
A2: # | B2: WCAG Criterion | C2: Level | D2: Description / What to Check | E2: Owner | F2: Status | G2: Notes
A3: Form Labels & Errors
A4: 1 | B4: 3.3.2 | C4: A | D4: All form fields have a visible, persistent label (not placeholder-only) | E4: QA / Content | F4: Pass
A5: 2 | B5: 3.3.1 | C5: A | D5: Errors are clearly identified and described in text next to / above the field | E5: QA / Content | F5: Pass
A6: 3 | B6: 3.3.3 | C6: AA | D6: Error suggestions tell users exactly how to correct invalid input | E6: QA / Content | F6: Pass
A7: 4 | B7: 3.3.4 | C7: AA | D7: Confirmation step provided before submitting financial or legal actions | E7: QA / Designer | F7: N/A | G7: Third party site (stripe) used for financial actions, not tested
A8: 5 | B8: 3.3.7 | C8: A | D8: User is not asked to re-enter data already provided in the same session | E8: QA / Designer | F8: Pass
A9: 6 | B9: 3.3.8 | C9: AA | D9: Login / authentication does not require solving a cognitive test (e.g. CAPTCHA) | E9: QA / Designer | F9: Pass
A10: 7 | B10: 1.3.5 | C10: AA | D10: Autocomplete attributes on name, email, address and phone fields are correct | E10: QA / Developer | F10: Pass | G10: Autocomplete present on some but not all fields (varies by form). Those present are correct
A11: 8 | B11: 4.1.2 | C11: A | D11: Required fields are marked programmatically (aria-required or required attr) | E11: QA / Developer | F11: Pass
A12: 9 | B12: 1.3.1 | C12: A | D12: Related fields are grouped with fieldset and legend elements | E12: QA / Developer | F12: Pass
A13: Best Practice
A14: 10 | B14: — | C14: BP | D14: Error summary provided at top of page on submission failure | E14: QA / Content | F14: Pass | G14: Summary on Donate form and browser error message on Get help form. Hubspot forms (webinars) do not show summary.
A15: 11 | B15: — | C15: BP | D15: Success confirmation is announced to screen readers via ARIA live region | E15: QA / Developer | F15: Fail | G15: Third party forms do not make use or ARIA live regions

Sheet QA_Colour
A1: Section 6 — QA: Colour & Contrast
A2: # | B2: WCAG Criterion | C2: Level | D2: Description / What to Check | E2: Owner | F2: Status | G2: Notes
A3: Contrast Ratios
A4: 1 | B4: 1.4.3 | C4: AA | D4: Normal text (below 18pt / 14pt bold): contrast ratio ≥ 4.5:1 | E4: Designer / QA | F4: Pass
A5: 2 | B5: 1.4.3 | C5: AA | D5: Large text (18pt+ / 14pt+ bold): contrast ratio ≥ 3:1 | E5: Designer / QA | F5: Pass
A6: 3 | B6: 1.4.11 | C6: AA | D6: UI components (buttons, inputs, icons) have ≥ 3:1 contrast against background | E6: Designer / QA | F6: Pass
A7: 4 | B7: 1.4.11 | C7: AA | D7: Focus indicators have ≥ 3:1 contrast against adjacent colours | E7: Designer / QA | F7: Pass | G7: Blue focus indicator does not meet colour contrast against purple, but extra white outline appears on this background.
A8: 5 | B8: 1.4.1 | C8: A | D8: Information is not conveyed by colour alone (e.g. red = error) | E8: Designer / QA | F8: Pass

Sheet QA_ScreenReader
A1: Section 7 — QA: Screen Reader
A2: # | B2: WCAG Criterion | C2: Level | D2: Description / What to Check | E2: Owner | F2: Status | G2: Notes
A3: Screen Reader Checks
A4: 1 | B4: 1.1.1 | C4: A | D4: All meaningful images have descriptive alt text; decorative images have alt="" | E4: QA / Content | F4: Fail
A5: 2 | B5: 1.3.1 | C5: A | D5: Page structure (landmarks, headings, lists) is announced correctly | E5: QA / Developer | F5: Pass
A6: 3 | B6: 2.4.2 | C6: A | D6: Page title is unique, descriptive and announced on page load | E6: QA / Content | F6: Pass
A7: 4 | B7: 2.4.4 | C7: A | D7: All links and buttons have descriptive accessible names (not 'click here') | E7: QA / Content | F7: Fail
A8: 5 | B8: 3.1.1 | C8: A | D8: Screen reader announces content in the correct human language | E8: QA / Developer | F8: Pass
A9: 6 | B9: 3.1.2 | C9: AA | D9: Inline language changes are announced correctly by the screen reader | E9: QA / Developer | F9: N/A
A10: 7 | B10: 4.1.2 | C10: A | D10: Custom controls expose correct role, name and state to screen readers | E10: QA / Developer | F10: Pass
A11: 8 | B11: 4.1.3 | C11: AA | D11: Dynamic content updates (alerts, validation, status) are announced | E11: QA / Developer | F11: Fail | G11: Error message on donate form announced as "undefined" after failed form submission
A12: 9 | B12: 2.5.3 | C12: A | D12: Visible button/link labels match or are included in the accessible name | E12: QA / Developer | F12: Pass
A13: Best Practice
A14: 10 | B14: — | C14: BP | D14: Test with VoiceOver + Safari (iOS/macOS) | E14: QA | F14: Pass | G14: Tested, see note below
A15: 11 | B15: — | C15: BP | D15: Reading order announced by screen reader matches visual reading order | E15: QA / Developer | F15: Pass | G15: Screen reader can announce everything that's accesible to it - it currently get's stuck within the menu. Tabbing is an acceptable route down the page.

Sheet QA_Media
A1: Section 8 — QA: Media
